2021-10-02 17:21:59,411:ERROR:Unable to open image url : name 'img_url' is not defined
Traceback (most recent call last):
  File "C:\Users\Johns\Desktop\Udacity\Meme_Generator\app.py", line 91, in meme_post
    img_content = requests.get(img_url, stream=True).content
NameError: name 'img_url' is not defined
2021-10-03 14:14:52,126:ERROR:Unable to open image url : name 'img_url' is not defined
Traceback (most recent call last):
  File "C:\Users\Johns\Desktop\Udacity\Meme_Generator\app.py", line 91, in meme_post
    img_content = requests.get(img_url, stream=True).content
NameError: name 'img_url' is not defined
2021-10-03 14:15:30,985:ERROR:Unable to open image url : name 'img_url' is not defined
Traceback (most recent call last):
  File "C:\Users\Johns\Desktop\Udacity\Meme_Generator\app.py", line 91, in meme_post
    img_content = requests.get(img_url, stream=True).content
NameError: name 'img_url' is not defined
2021-10-03 14:16:14,392:ERROR:Unable to open image url : name 'img_url' is not defined
Traceback (most recent call last):
  File "C:\Users\Johns\Desktop\Udacity\Meme_Generator\app.py", line 91, in meme_post
    img_content = requests.get(img_url, stream=True).content
NameError: name 'img_url' is not defined
2021-10-03 14:55:39,127:ERROR:Unable to open image url : HTTPSConnectionPool(host='www.automobiledimension.com', port=443): Max retries exceeded with url: /photos/fiat-500-2021.jpg (Caused by SSLError(SSLCertVerificationError(1, '[SSL: CERTIFICATE_VERIFY_FAILED] certificate verify failed: unable to get local issuer certificate (_ssl.c:1123)')))
Traceback (most recent call last):
  File "C:\Users\Johns\Desktop\Udacity\Meme_Generator\venv\lib\site-packages\urllib3\connectionpool.py", line 699, in urlopen
    httplib_response = self._make_request(
  File "C:\Users\Johns\Desktop\Udacity\Meme_Generator\venv\lib\site-packages\urllib3\connectionpool.py", line 382, in _make_request
    self._validate_conn(conn)
  File "C:\Users\Johns\Desktop\Udacity\Meme_Generator\venv\lib\site-packages\urllib3\connectionpool.py", line 1010, in _validate_conn
    conn.connect()
  File "C:\Users\Johns\Desktop\Udacity\Meme_Generator\venv\lib\site-packages\urllib3\connection.py", line 416, in connect
    self.sock = ssl_wrap_socket(
  File "C:\Users\Johns\Desktop\Udacity\Meme_Generator\venv\lib\site-packages\urllib3\util\ssl_.py", line 449, in ssl_wrap_socket
    ssl_sock = _ssl_wrap_socket_impl(
  File "C:\Users\Johns\Desktop\Udacity\Meme_Generator\venv\lib\site-packages\urllib3\util\ssl_.py", line 493, in _ssl_wrap_socket_impl
    return ssl_context.wrap_socket(sock, server_hostname=server_hostname)
  File "C:\Users\Johns\AppData\Local\Programs\Python\Python39\lib\ssl.py", line 500, in wrap_socket
    return self.sslsocket_class._create(
  File "C:\Users\Johns\AppData\Local\Programs\Python\Python39\lib\ssl.py", line 1040, in _create
    self.do_handshake()
  File "C:\Users\Johns\AppData\Local\Programs\Python\Python39\lib\ssl.py", line 1309, in do_handshake
    self._sslobj.do_handshake()
ssl.SSLCertVerificationError: [SSL: CERTIFICATE_VERIFY_FAILED] certificate verify failed: unable to get local issuer certificate (_ssl.c:1123)

During handling of the above exception, another exception occurred:

Traceback (most recent call last):
  File "C:\Users\Johns\Desktop\Udacity\Meme_Generator\venv\lib\site-packages\requests\adapters.py", line 439, in send
    resp = conn.urlopen(
  File "C:\Users\Johns\Desktop\Udacity\Meme_Generator\venv\lib\site-packages\urllib3\connectionpool.py", line 755, in urlopen
    retries = retries.increment(
  File "C:\Users\Johns\Desktop\Udacity\Meme_Generator\venv\lib\site-packages\urllib3\util\retry.py", line 574, in increment
    raise MaxRetryError(_pool, url, error or ResponseError(cause))
urllib3.exceptions.MaxRetryError: HTTPSConnectionPool(host='www.automobiledimension.com', port=443): Max retries exceeded with url: /photos/fiat-500-2021.jpg (Caused by SSLError(SSLCertVerificationError(1, '[SSL: CERTIFICATE_VERIFY_FAILED] certificate verify failed: unable to get local issuer certificate (_ssl.c:1123)')))

During handling of the above exception, another exception occurred:

Traceback (most recent call last):
  File "C:\Users\Johns\Desktop\Udacity\Meme_Generator\app.py", line 91, in meme_post
    img_content = requests.get(image_url, stream=True).content
  File "C:\Users\Johns\Desktop\Udacity\Meme_Generator\venv\lib\site-packages\requests\api.py", line 75, in get
    return request('get', url, params=params, **kwargs)
  File "C:\Users\Johns\Desktop\Udacity\Meme_Generator\venv\lib\site-packages\requests\api.py", line 61, in request
    return session.request(method=method, url=url, **kwargs)
  File "C:\Users\Johns\Desktop\Udacity\Meme_Generator\venv\lib\site-packages\requests\sessions.py", line 542, in request
    resp = self.send(prep, **send_kwargs)
  File "C:\Users\Johns\Desktop\Udacity\Meme_Generator\venv\lib\site-packages\requests\sessions.py", line 655, in send
    r = adapter.send(request, **kwargs)
  File "C:\Users\Johns\Desktop\Udacity\Meme_Generator\venv\lib\site-packages\requests\adapters.py", line 514, in send
    raise SSLError(e, request=request)
requests.exceptions.SSLError: HTTPSConnectionPool(host='www.automobiledimension.com', port=443): Max retries exceeded with url: /photos/fiat-500-2021.jpg (Caused by SSLError(SSLCertVerificationError(1, '[SSL: CERTIFICATE_VERIFY_FAILED] certificate verify failed: unable to get local issuer certificate (_ssl.c:1123)')))
2021-10-03 15:01:28,132:ERROR:Unable to create meme: cannot identify image file './static/176564.jpg'
Traceback (most recent call last):
  File "C:\Users\Johns\Desktop\Udacity\Meme_Generator\app.py", line 103, in meme_post
    path = meme.make_meme(tmp, body, author)
  File "C:\Users\Johns\Desktop\Udacity\Meme_Generator\MemeGenerator\MemeEngine.py", line 63, in make_meme
    img = image_resize(img_path, width)
  File "C:\Users\Johns\Desktop\Udacity\Meme_Generator\utils.py", line 113, in image_resize
    with Image.open(img_path) as img:
  File "C:\Users\Johns\Desktop\Udacity\Meme_Generator\venv\lib\site-packages\PIL\Image.py", line 3023, in open
    raise UnidentifiedImageError(
PIL.UnidentifiedImageError: cannot identify image file './static/176564.jpg'
2021-10-03 15:01:43,502:ERROR:Unable to create meme: cannot identify image file './static/848557.jpg'
Traceback (most recent call last):
  File "C:\Users\Johns\Desktop\Udacity\Meme_Generator\app.py", line 103, in meme_post
    path = meme.make_meme(tmp, body, author)
  File "C:\Users\Johns\Desktop\Udacity\Meme_Generator\MemeGenerator\MemeEngine.py", line 63, in make_meme
    img = image_resize(img_path, width)
  File "C:\Users\Johns\Desktop\Udacity\Meme_Generator\utils.py", line 113, in image_resize
    with Image.open(img_path) as img:
  File "C:\Users\Johns\Desktop\Udacity\Meme_Generator\venv\lib\site-packages\PIL\Image.py", line 3023, in open
    raise UnidentifiedImageError(
PIL.UnidentifiedImageError: cannot identify image file './static/848557.jpg'
2021-10-03 15:01:51,854:ERROR:Unable to create meme: cannot identify image file './static/880396.jpg'
Traceback (most recent call last):
  File "C:\Users\Johns\Desktop\Udacity\Meme_Generator\app.py", line 103, in meme_post
    path = meme.make_meme(tmp, body, author)
  File "C:\Users\Johns\Desktop\Udacity\Meme_Generator\MemeGenerator\MemeEngine.py", line 63, in make_meme
    img = image_resize(img_path, width)
  File "C:\Users\Johns\Desktop\Udacity\Meme_Generator\utils.py", line 113, in image_resize
    with Image.open(img_path) as img:
  File "C:\Users\Johns\Desktop\Udacity\Meme_Generator\venv\lib\site-packages\PIL\Image.py", line 3023, in open
    raise UnidentifiedImageError(
PIL.UnidentifiedImageError: cannot identify image file './static/880396.jpg'
2021-10-03 15:01:59,420:ERROR:Unable to create meme: cannot identify image file './static/663580.jpg'
Traceback (most recent call last):
  File "C:\Users\Johns\Desktop\Udacity\Meme_Generator\app.py", line 103, in meme_post
    path = meme.make_meme(tmp, body, author)
  File "C:\Users\Johns\Desktop\Udacity\Meme_Generator\MemeGenerator\MemeEngine.py", line 63, in make_meme
    img = image_resize(img_path, width)
  File "C:\Users\Johns\Desktop\Udacity\Meme_Generator\utils.py", line 113, in image_resize
    with Image.open(img_path) as img:
  File "C:\Users\Johns\Desktop\Udacity\Meme_Generator\venv\lib\site-packages\PIL\Image.py", line 3023, in open
    raise UnidentifiedImageError(
PIL.UnidentifiedImageError: cannot identify image file './static/663580.jpg'
2021-10-03 15:02:34,052:ERROR:Unable to open image url : HTTPSConnectionPool(host='www.automobiledimension.com', port=443): Max retries exceeded with url: /photos/fiat-500-2021.jpg (Caused by SSLError(SSLCertVerificationError(1, '[SSL: CERTIFICATE_VERIFY_FAILED] certificate verify failed: unable to get local issuer certificate (_ssl.c:1123)')))
Traceback (most recent call last):
  File "C:\Users\Johns\Desktop\Udacity\Meme_Generator\venv\lib\site-packages\urllib3\connectionpool.py", line 699, in urlopen
    httplib_response = self._make_request(
  File "C:\Users\Johns\Desktop\Udacity\Meme_Generator\venv\lib\site-packages\urllib3\connectionpool.py", line 382, in _make_request
    self._validate_conn(conn)
  File "C:\Users\Johns\Desktop\Udacity\Meme_Generator\venv\lib\site-packages\urllib3\connectionpool.py", line 1010, in _validate_conn
    conn.connect()
  File "C:\Users\Johns\Desktop\Udacity\Meme_Generator\venv\lib\site-packages\urllib3\connection.py", line 416, in connect
    self.sock = ssl_wrap_socket(
  File "C:\Users\Johns\Desktop\Udacity\Meme_Generator\venv\lib\site-packages\urllib3\util\ssl_.py", line 449, in ssl_wrap_socket
    ssl_sock = _ssl_wrap_socket_impl(
  File "C:\Users\Johns\Desktop\Udacity\Meme_Generator\venv\lib\site-packages\urllib3\util\ssl_.py", line 493, in _ssl_wrap_socket_impl
    return ssl_context.wrap_socket(sock, server_hostname=server_hostname)
  File "C:\Users\Johns\AppData\Local\Programs\Python\Python39\lib\ssl.py", line 500, in wrap_socket
    return self.sslsocket_class._create(
  File "C:\Users\Johns\AppData\Local\Programs\Python\Python39\lib\ssl.py", line 1040, in _create
    self.do_handshake()
  File "C:\Users\Johns\AppData\Local\Programs\Python\Python39\lib\ssl.py", line 1309, in do_handshake
    self._sslobj.do_handshake()
ssl.SSLCertVerificationError: [SSL: CERTIFICATE_VERIFY_FAILED] certificate verify failed: unable to get local issuer certificate (_ssl.c:1123)

During handling of the above exception, another exception occurred:

Traceback (most recent call last):
  File "C:\Users\Johns\Desktop\Udacity\Meme_Generator\venv\lib\site-packages\requests\adapters.py", line 439, in send
    resp = conn.urlopen(
  File "C:\Users\Johns\Desktop\Udacity\Meme_Generator\venv\lib\site-packages\urllib3\connectionpool.py", line 755, in urlopen
    retries = retries.increment(
  File "C:\Users\Johns\Desktop\Udacity\Meme_Generator\venv\lib\site-packages\urllib3\util\retry.py", line 574, in increment
    raise MaxRetryError(_pool, url, error or ResponseError(cause))
urllib3.exceptions.MaxRetryError: HTTPSConnectionPool(host='www.automobiledimension.com', port=443): Max retries exceeded with url: /photos/fiat-500-2021.jpg (Caused by SSLError(SSLCertVerificationError(1, '[SSL: CERTIFICATE_VERIFY_FAILED] certificate verify failed: unable to get local issuer certificate (_ssl.c:1123)')))

During handling of the above exception, another exception occurred:

Traceback (most recent call last):
  File "C:\Users\Johns\Desktop\Udacity\Meme_Generator\app.py", line 91, in meme_post
    img_content = requests.get(image_url, stream=True).content
  File "C:\Users\Johns\Desktop\Udacity\Meme_Generator\venv\lib\site-packages\requests\api.py", line 75, in get
    return request('get', url, params=params, **kwargs)
  File "C:\Users\Johns\Desktop\Udacity\Meme_Generator\venv\lib\site-packages\requests\api.py", line 61, in request
    return session.request(method=method, url=url, **kwargs)
  File "C:\Users\Johns\Desktop\Udacity\Meme_Generator\venv\lib\site-packages\requests\sessions.py", line 542, in request
    resp = self.send(prep, **send_kwargs)
  File "C:\Users\Johns\Desktop\Udacity\Meme_Generator\venv\lib\site-packages\requests\sessions.py", line 655, in send
    r = adapter.send(request, **kwargs)
  File "C:\Users\Johns\Desktop\Udacity\Meme_Generator\venv\lib\site-packages\requests\adapters.py", line 514, in send
    raise SSLError(e, request=request)
requests.exceptions.SSLError: HTTPSConnectionPool(host='www.automobiledimension.com', port=443): Max retries exceeded with url: /photos/fiat-500-2021.jpg (Caused by SSLError(SSLCertVerificationError(1, '[SSL: CERTIFICATE_VERIFY_FAILED] certificate verify failed: unable to get local issuer certificate (_ssl.c:1123)')))
2021-10-03 15:03:08,427:ERROR:Unable to create meme: cannot identify image file './static/486247.jpg'
Traceback (most recent call last):
  File "C:\Users\Johns\Desktop\Udacity\Meme_Generator\app.py", line 103, in meme_post
    path = meme.make_meme(tmp, body, author)
  File "C:\Users\Johns\Desktop\Udacity\Meme_Generator\MemeGenerator\MemeEngine.py", line 63, in make_meme
    img = image_resize(img_path, width)
  File "C:\Users\Johns\Desktop\Udacity\Meme_Generator\utils.py", line 113, in image_resize
    with Image.open(img_path) as img:
  File "C:\Users\Johns\Desktop\Udacity\Meme_Generator\venv\lib\site-packages\PIL\Image.py", line 3023, in open
    raise UnidentifiedImageError(
PIL.UnidentifiedImageError: cannot identify image file './static/486247.jpg'
2021-10-04 14:36:11,474:ERROR:Unable to create meme: cannot identify image file './static/125446.jpg'
Traceback (most recent call last):
  File "C:\Users\Johns\Desktop\Udacity\Meme_Generator\app.py", line 103, in meme_post
    path = meme.make_meme(tmp, body, author)
  File "C:\Users\Johns\Desktop\Udacity\Meme_Generator\MemeGenerator\MemeEngine.py", line 63, in make_meme
    img = image_resize(img_path, width)
  File "C:\Users\Johns\Desktop\Udacity\Meme_Generator\utils.py", line 113, in image_resize
    with Image.open(img_path) as img:
  File "C:\Users\Johns\Desktop\Udacity\Meme_Generator\venv\lib\site-packages\PIL\Image.py", line 3023, in open
    raise UnidentifiedImageError(
PIL.UnidentifiedImageError: cannot identify image file './static/125446.jpg'
2021-10-04 14:39:12,539:ERROR:Unable to create meme: 'Logger' object has no attribute 'INFO'
Traceback (most recent call last):
  File "C:\Users\Johns\Desktop\Udacity\Meme_Generator\app.py", line 103, in meme_post
    path = meme.make_meme(tmp, body, author)
  File "C:\Users\Johns\Desktop\Udacity\Meme_Generator\MemeGenerator\MemeEngine.py", line 63, in make_meme
    img = image_resize(img_path, width)
  File "C:\Users\Johns\Desktop\Udacity\Meme_Generator\utils.py", line 128, in image_resize
    logger.INFO(f'{img_path}')
AttributeError: 'Logger' object has no attribute 'INFO'
2021-10-04 14:42:52,739:ERROR:Unable to create meme: cannot identify image file './static/596296.jpg'
Traceback (most recent call last):
  File "C:\Users\Johns\Desktop\Udacity\Meme_Generator\app.py", line 103, in meme_post
    path = meme.make_meme(tmp, body, author)
  File "C:\Users\Johns\Desktop\Udacity\Meme_Generator\MemeGenerator\MemeEngine.py", line 63, in make_meme
    img = image_resize(img_path, width)
  File "C:\Users\Johns\Desktop\Udacity\Meme_Generator\utils.py", line 129, in image_resize
    with Image.open(img_path) as img:
  File "C:\Users\Johns\Desktop\Udacity\Meme_Generator\venv\lib\site-packages\PIL\Image.py", line 3023, in open
    raise UnidentifiedImageError(
PIL.UnidentifiedImageError: cannot identify image file './static/596296.jpg'
2021-10-04 14:47:05,507:ERROR:Unable to create meme: cannot identify image file './static/963.jpg'
Traceback (most recent call last):
  File "C:\Users\Johns\Desktop\Udacity\Meme_Generator\app.py", line 103, in meme_post
    path = meme.make_meme(tmp, body, author)
  File "C:\Users\Johns\Desktop\Udacity\Meme_Generator\MemeGenerator\MemeEngine.py", line 63, in make_meme
    img = image_resize(img_path, width)
  File "C:\Users\Johns\Desktop\Udacity\Meme_Generator\utils.py", line 128, in image_resize
    with Image.open(img_path) as img:
  File "C:\Users\Johns\Desktop\Udacity\Meme_Generator\venv\lib\site-packages\PIL\Image.py", line 3023, in open
    raise UnidentifiedImageError(
PIL.UnidentifiedImageError: cannot identify image file './static/963.jpg'
2021-10-04 14:47:17,245:ERROR:Unable to create meme: cannot identify image file './static/507.jpg'
Traceback (most recent call last):
  File "C:\Users\Johns\Desktop\Udacity\Meme_Generator\app.py", line 103, in meme_post
    path = meme.make_meme(tmp, body, author)
  File "C:\Users\Johns\Desktop\Udacity\Meme_Generator\MemeGenerator\MemeEngine.py", line 63, in make_meme
    img = image_resize(img_path, width)
  File "C:\Users\Johns\Desktop\Udacity\Meme_Generator\utils.py", line 128, in image_resize
    with Image.open(img_path) as img:
  File "C:\Users\Johns\Desktop\Udacity\Meme_Generator\venv\lib\site-packages\PIL\Image.py", line 3023, in open
    raise UnidentifiedImageError(
PIL.UnidentifiedImageError: cannot identify image file './static/507.jpg'
2021-10-04 15:01:53,605:ERROR:Unable to create meme: cannot identify image file './static/239.jpg'
Traceback (most recent call last):
  File "C:\Users\Johns\Desktop\Udacity\Meme_Generator\app.py", line 103, in meme_post
    path = meme.make_meme(tmp, body, author)
  File "C:\Users\Johns\Desktop\Udacity\Meme_Generator\MemeGenerator\MemeEngine.py", line 63, in make_meme
    img = image_resize(img_path, width)
  File "C:\Users\Johns\Desktop\Udacity\Meme_Generator\utils.py", line 128, in image_resize
    with Image.open(img_path) as img:
  File "C:\Users\Johns\Desktop\Udacity\Meme_Generator\venv\lib\site-packages\PIL\Image.py", line 3023, in open
    raise UnidentifiedImageError(
PIL.UnidentifiedImageError: cannot identify image file './static/239.jpg'
2021-10-04 15:02:41,386:ERROR:Unable to create meme: cannot identify image file './static/627.jpg'
Traceback (most recent call last):
  File "C:\Users\Johns\Desktop\Udacity\Meme_Generator\app.py", line 103, in meme_post
    path = meme.make_meme(tmp, body, author)
  File "C:\Users\Johns\Desktop\Udacity\Meme_Generator\MemeGenerator\MemeEngine.py", line 63, in make_meme
    img = image_resize(img_path, width)
  File "C:\Users\Johns\Desktop\Udacity\Meme_Generator\utils.py", line 128, in image_resize
    with Image.open(img_path) as img:
  File "C:\Users\Johns\Desktop\Udacity\Meme_Generator\venv\lib\site-packages\PIL\Image.py", line 3023, in open
    raise UnidentifiedImageError(
PIL.UnidentifiedImageError: cannot identify image file './static/627.jpg'
2021-10-04 15:03:36,557:ERROR:Unable to create meme: cannot identify image file './static/959.jpg'
Traceback (most recent call last):
  File "C:\Users\Johns\Desktop\Udacity\Meme_Generator\app.py", line 103, in meme_post
    path = meme.make_meme(tmp, body, author)
  File "C:\Users\Johns\Desktop\Udacity\Meme_Generator\MemeGenerator\MemeEngine.py", line 63, in make_meme
    img = image_resize(img_path, width)
  File "C:\Users\Johns\Desktop\Udacity\Meme_Generator\utils.py", line 128, in image_resize
    with Image.open(img_path) as img:
  File "C:\Users\Johns\Desktop\Udacity\Meme_Generator\venv\lib\site-packages\PIL\Image.py", line 3023, in open
    raise UnidentifiedImageError(
PIL.UnidentifiedImageError: cannot identify image file './static/959.jpg'
2021-10-04 15:06:12,072:ERROR:Unable to create meme: seek of closed file
Traceback (most recent call last):
  File "C:\Users\Johns\Desktop\Udacity\Meme_Generator\app.py", line 103, in meme_post
    path = meme.make_meme(tmp, body, author)
  File "C:\Users\Johns\Desktop\Udacity\Meme_Generator\MemeGenerator\MemeEngine.py", line 63, in make_meme
    img = image_resize(img_path, width)
  File "C:\Users\Johns\Desktop\Udacity\Meme_Generator\utils.py", line 128, in image_resize
    with Image.open(img_path) as img:
  File "C:\Users\Johns\Desktop\Udacity\Meme_Generator\venv\lib\site-packages\PIL\Image.py", line 2972, in open
    fp.seek(0)
ValueError: seek of closed file
2021-10-04 15:08:42,710:ERROR:Unable to create meme: cannot identify image file './static/643.jpg'
Traceback (most recent call last):
  File "C:\Users\Johns\Desktop\Udacity\Meme_Generator\app.py", line 104, in meme_post
    path = meme.make_meme(tmp, body, author)
  File "C:\Users\Johns\Desktop\Udacity\Meme_Generator\MemeGenerator\MemeEngine.py", line 63, in make_meme
    img = image_resize(img_path, width)
  File "C:\Users\Johns\Desktop\Udacity\Meme_Generator\utils.py", line 128, in image_resize
    with Image.open(img_path) as img:
  File "C:\Users\Johns\Desktop\Udacity\Meme_Generator\venv\lib\site-packages\PIL\Image.py", line 3023, in open
    raise UnidentifiedImageError(
PIL.UnidentifiedImageError: cannot identify image file './static/643.jpg'
2021-10-04 15:12:22,201:ERROR:Unable to create meme: cannot identify image file './static/844.jpg'
Traceback (most recent call last):
  File "C:\Users\Johns\Desktop\Udacity\Meme_Generator\app.py", line 104, in meme_post
    path = meme.make_meme(tmp, body, author)
  File "C:\Users\Johns\Desktop\Udacity\Meme_Generator\MemeGenerator\MemeEngine.py", line 63, in make_meme
    img = image_resize(img_path, width)
  File "C:\Users\Johns\Desktop\Udacity\Meme_Generator\utils.py", line 128, in image_resize
    with Image.open(img_path) as img:
  File "C:\Users\Johns\Desktop\Udacity\Meme_Generator\venv\lib\site-packages\PIL\Image.py", line 3023, in open
    raise UnidentifiedImageError(
PIL.UnidentifiedImageError: cannot identify image file './static/844.jpg'
2021-10-04 15:12:28,607:ERROR:Unable to open image url : HTTPSConnectionPool(host='www.automobiledimension.com', port=443): Max retries exceeded with url: /photos/fiat-500-2021.jpg (Caused by SSLError(SSLCertVerificationError(1, '[SSL: CERTIFICATE_VERIFY_FAILED] certificate verify failed: unable to get local issuer certificate (_ssl.c:1123)')))
Traceback (most recent call last):
  File "C:\Users\Johns\Desktop\Udacity\Meme_Generator\venv\lib\site-packages\urllib3\connectionpool.py", line 699, in urlopen
    httplib_response = self._make_request(
  File "C:\Users\Johns\Desktop\Udacity\Meme_Generator\venv\lib\site-packages\urllib3\connectionpool.py", line 382, in _make_request
    self._validate_conn(conn)
  File "C:\Users\Johns\Desktop\Udacity\Meme_Generator\venv\lib\site-packages\urllib3\connectionpool.py", line 1010, in _validate_conn
    conn.connect()
  File "C:\Users\Johns\Desktop\Udacity\Meme_Generator\venv\lib\site-packages\urllib3\connection.py", line 416, in connect
    self.sock = ssl_wrap_socket(
  File "C:\Users\Johns\Desktop\Udacity\Meme_Generator\venv\lib\site-packages\urllib3\util\ssl_.py", line 449, in ssl_wrap_socket
    ssl_sock = _ssl_wrap_socket_impl(
  File "C:\Users\Johns\Desktop\Udacity\Meme_Generator\venv\lib\site-packages\urllib3\util\ssl_.py", line 493, in _ssl_wrap_socket_impl
    return ssl_context.wrap_socket(sock, server_hostname=server_hostname)
  File "C:\Users\Johns\AppData\Local\Programs\Python\Python39\lib\ssl.py", line 500, in wrap_socket
    return self.sslsocket_class._create(
  File "C:\Users\Johns\AppData\Local\Programs\Python\Python39\lib\ssl.py", line 1040, in _create
    self.do_handshake()
  File "C:\Users\Johns\AppData\Local\Programs\Python\Python39\lib\ssl.py", line 1309, in do_handshake
    self._sslobj.do_handshake()
ssl.SSLCertVerificationError: [SSL: CERTIFICATE_VERIFY_FAILED] certificate verify failed: unable to get local issuer certificate (_ssl.c:1123)

During handling of the above exception, another exception occurred:

Traceback (most recent call last):
  File "C:\Users\Johns\Desktop\Udacity\Meme_Generator\venv\lib\site-packages\requests\adapters.py", line 439, in send
    resp = conn.urlopen(
  File "C:\Users\Johns\Desktop\Udacity\Meme_Generator\venv\lib\site-packages\urllib3\connectionpool.py", line 755, in urlopen
    retries = retries.increment(
  File "C:\Users\Johns\Desktop\Udacity\Meme_Generator\venv\lib\site-packages\urllib3\util\retry.py", line 574, in increment
    raise MaxRetryError(_pool, url, error or ResponseError(cause))
urllib3.exceptions.MaxRetryError: HTTPSConnectionPool(host='www.automobiledimension.com', port=443): Max retries exceeded with url: /photos/fiat-500-2021.jpg (Caused by SSLError(SSLCertVerificationError(1, '[SSL: CERTIFICATE_VERIFY_FAILED] certificate verify failed: unable to get local issuer certificate (_ssl.c:1123)')))

During handling of the above exception, another exception occurred:

Traceback (most recent call last):
  File "C:\Users\Johns\Desktop\Udacity\Meme_Generator\app.py", line 91, in meme_post
    img_content = requests.get(image_url, stream=True).content
  File "C:\Users\Johns\Desktop\Udacity\Meme_Generator\venv\lib\site-packages\requests\api.py", line 75, in get
    return request('get', url, params=params, **kwargs)
  File "C:\Users\Johns\Desktop\Udacity\Meme_Generator\venv\lib\site-packages\requests\api.py", line 61, in request
    return session.request(method=method, url=url, **kwargs)
  File "C:\Users\Johns\Desktop\Udacity\Meme_Generator\venv\lib\site-packages\requests\sessions.py", line 542, in request
    resp = self.send(prep, **send_kwargs)
  File "C:\Users\Johns\Desktop\Udacity\Meme_Generator\venv\lib\site-packages\requests\sessions.py", line 655, in send
    r = adapter.send(request, **kwargs)
  File "C:\Users\Johns\Desktop\Udacity\Meme_Generator\venv\lib\site-packages\requests\adapters.py", line 514, in send
    raise SSLError(e, request=request)
requests.exceptions.SSLError: HTTPSConnectionPool(host='www.automobiledimension.com', port=443): Max retries exceeded with url: /photos/fiat-500-2021.jpg (Caused by SSLError(SSLCertVerificationError(1, '[SSL: CERTIFICATE_VERIFY_FAILED] certificate verify failed: unable to get local issuer certificate (_ssl.c:1123)')))
2021-10-04 15:12:38,189:ERROR:Unable to create meme: cannot identify image file './static/228.jpg'
Traceback (most recent call last):
  File "C:\Users\Johns\Desktop\Udacity\Meme_Generator\app.py", line 104, in meme_post
    path = meme.make_meme(tmp, body, author)
  File "C:\Users\Johns\Desktop\Udacity\Meme_Generator\MemeGenerator\MemeEngine.py", line 63, in make_meme
    img = image_resize(img_path, width)
  File "C:\Users\Johns\Desktop\Udacity\Meme_Generator\utils.py", line 128, in image_resize
    with Image.open(img_path) as img:
  File "C:\Users\Johns\Desktop\Udacity\Meme_Generator\venv\lib\site-packages\PIL\Image.py", line 3023, in open
    raise UnidentifiedImageError(
PIL.UnidentifiedImageError: cannot identify image file './static/228.jpg'
2021-10-04 15:12:45,552:ERROR:Unable to open image url : No connection adapters were found for 'C:\\Users\\Johns\\Desktop\\Udacity\\Meme_Generator\\_data\\photos\\book\\pexels-andrea-piacquadio-3887493'
Traceback (most recent call last):
  File "C:\Users\Johns\Desktop\Udacity\Meme_Generator\app.py", line 91, in meme_post
    img_content = requests.get(image_url, stream=True).content
  File "C:\Users\Johns\Desktop\Udacity\Meme_Generator\venv\lib\site-packages\requests\api.py", line 75, in get
    return request('get', url, params=params, **kwargs)
  File "C:\Users\Johns\Desktop\Udacity\Meme_Generator\venv\lib\site-packages\requests\api.py", line 61, in request
    return session.request(method=method, url=url, **kwargs)
  File "C:\Users\Johns\Desktop\Udacity\Meme_Generator\venv\lib\site-packages\requests\sessions.py", line 542, in request
    resp = self.send(prep, **send_kwargs)
  File "C:\Users\Johns\Desktop\Udacity\Meme_Generator\venv\lib\site-packages\requests\sessions.py", line 649, in send
    adapter = self.get_adapter(url=request.url)
  File "C:\Users\Johns\Desktop\Udacity\Meme_Generator\venv\lib\site-packages\requests\sessions.py", line 742, in get_adapter
    raise InvalidSchema("No connection adapters were found for {!r}".format(url))
requests.exceptions.InvalidSchema: No connection adapters were found for 'C:\\Users\\Johns\\Desktop\\Udacity\\Meme_Generator\\_data\\photos\\book\\pexels-andrea-piacquadio-3887493'
2021-10-04 15:20:54,617:ERROR:Unable to create meme: cannot identify image file './static/296.jpg'
Traceback (most recent call last):
  File "C:\Users\Johns\Desktop\Udacity\Meme_Generator\app.py", line 104, in meme_post
    path = meme.make_meme(tmp, body, author)
  File "C:\Users\Johns\Desktop\Udacity\Meme_Generator\MemeGenerator\MemeEngine.py", line 63, in make_meme
    img = image_resize(img_path, width)
  File "C:\Users\Johns\Desktop\Udacity\Meme_Generator\utils.py", line 128, in image_resize
    with Image.open(img_path) as img:
  File "C:\Users\Johns\Desktop\Udacity\Meme_Generator\venv\lib\site-packages\PIL\Image.py", line 3023, in open
    raise UnidentifiedImageError(
PIL.UnidentifiedImageError: cannot identify image file './static/296.jpg'
2021-10-04 15:55:55,077:ERROR:Unable to create meme: cannot identify image file './static/354.jpg'
Traceback (most recent call last):
  File "C:\Users\Johns\Desktop\Udacity\Meme_Generator\app.py", line 104, in meme_post
    path = meme.make_meme(tmp, body, author)
  File "C:\Users\Johns\Desktop\Udacity\Meme_Generator\MemeGenerator\MemeEngine.py", line 63, in make_meme
    img = image_resize(img_path, width)
  File "C:\Users\Johns\Desktop\Udacity\Meme_Generator\utils.py", line 128, in image_resize
    with Image.open(img_path) as img:
  File "C:\Users\Johns\Desktop\Udacity\Meme_Generator\venv\lib\site-packages\PIL\Image.py", line 3023, in open
    raise UnidentifiedImageError(
PIL.UnidentifiedImageError: cannot identify image file './static/354.jpg'
2021-10-04 15:57:08,617:ERROR:Unable to create meme: cannot identify image file './static/982.jpg'
Traceback (most recent call last):
  File "C:\Users\Johns\Desktop\Udacity\Meme_Generator\app.py", line 104, in meme_post
    path = meme.make_meme(tmp, body, author)
  File "C:\Users\Johns\Desktop\Udacity\Meme_Generator\MemeGenerator\MemeEngine.py", line 63, in make_meme
    img = image_resize(img_path, width)
  File "C:\Users\Johns\Desktop\Udacity\Meme_Generator\utils.py", line 128, in image_resize
    with Image.open(img_path) as img:
  File "C:\Users\Johns\Desktop\Udacity\Meme_Generator\venv\lib\site-packages\PIL\Image.py", line 3023, in open
    raise UnidentifiedImageError(
PIL.UnidentifiedImageError: cannot identify image file './static/982.jpg'
2021-10-04 21:25:24,232:ERROR:Unable to generate meme : local variable 'img' referenced before assignment
Traceback (most recent call last):
  File "C:\Users\Johns\Desktop\Udacity\Meme_Generator\app.py", line 60, in meme_rand
    path = meme.make_meme(img, quote.body, quote.author)
  File "C:\Users\Johns\Desktop\Udacity\Meme_Generator\MemeGenerator\MemeEngine.py", line 63, in make_meme
    img = image_resize(img_path, width)
  File "C:\Users\Johns\Desktop\Udacity\Meme_Generator\utils.py", line 127, in image_resize
    logger.info(f'{img}')
UnboundLocalError: local variable 'img' referenced before assignment
2021-10-04 21:27:52,582:ERROR:Unable to generate meme : local variable 'img' referenced before assignment
Traceback (most recent call last):
  File "C:\Users\Johns\Desktop\Udacity\Meme_Generator\app.py", line 60, in meme_rand
    path = meme.make_meme(img, quote.body, quote.author)
  File "C:\Users\Johns\Desktop\Udacity\Meme_Generator\MemeGenerator\MemeEngine.py", line 63, in make_meme
    img = image_resize(img_path, width)
  File "C:\Users\Johns\Desktop\Udacity\Meme_Generator\utils.py", line 127, in image_resize
    logger.info(f'{img}')
UnboundLocalError: local variable 'img' referenced before assignment
2021-10-04 21:27:54,806:ERROR:Unable to generate meme : local variable 'img' referenced before assignment
Traceback (most recent call last):
  File "C:\Users\Johns\Desktop\Udacity\Meme_Generator\app.py", line 60, in meme_rand
    path = meme.make_meme(img, quote.body, quote.author)
  File "C:\Users\Johns\Desktop\Udacity\Meme_Generator\MemeGenerator\MemeEngine.py", line 63, in make_meme
    img = image_resize(img_path, width)
  File "C:\Users\Johns\Desktop\Udacity\Meme_Generator\utils.py", line 127, in image_resize
    logger.info(f'{img}')
UnboundLocalError: local variable 'img' referenced before assignment
2021-10-04 21:27:57,440:ERROR:Unable to generate meme : local variable 'img' referenced before assignment
Traceback (most recent call last):
  File "C:\Users\Johns\Desktop\Udacity\Meme_Generator\app.py", line 60, in meme_rand
    path = meme.make_meme(img, quote.body, quote.author)
  File "C:\Users\Johns\Desktop\Udacity\Meme_Generator\MemeGenerator\MemeEngine.py", line 63, in make_meme
    img = image_resize(img_path, width)
  File "C:\Users\Johns\Desktop\Udacity\Meme_Generator\utils.py", line 127, in image_resize
    logger.info(f'{img}')
UnboundLocalError: local variable 'img' referenced before assignment
2021-10-04 21:29:01,020:ERROR:Unable to create meme: local variable 'img' referenced before assignment
Traceback (most recent call last):
  File "C:\Users\Johns\Desktop\Udacity\Meme_Generator\app.py", line 104, in meme_post
    path = meme.make_meme(tmp, body, author)
  File "C:\Users\Johns\Desktop\Udacity\Meme_Generator\MemeGenerator\MemeEngine.py", line 63, in make_meme
    img = image_resize(img_path, width)
  File "C:\Users\Johns\Desktop\Udacity\Meme_Generator\utils.py", line 127, in image_resize
    logger.info(f'{img}')
UnboundLocalError: local variable 'img' referenced before assignment
2021-10-04 21:51:22,757:ERROR:Unable to create meme: 'ImageDraw' object has no attribute 'size'
Traceback (most recent call last):
  File "C:\Users\Johns\Desktop\Udacity\Meme_Generator\app.py", line 104, in meme_post
    path = meme.make_meme(tmp, body, author)
  File "C:\Users\Johns\Desktop\Udacity\Meme_Generator\MemeGenerator\MemeEngine.py", line 69, in make_meme
    text_draw(draw, text, author, fill, font)
  File "C:\Users\Johns\Desktop\Udacity\Meme_Generator\utils.py", line 155, in text_draw
    width, height = draw.size
AttributeError: 'ImageDraw' object has no attribute 'size'
2021-10-04 21:56:26,448:ERROR:Unable to create meme: non-integer stop for randrange()
Traceback (most recent call last):
  File "C:\Users\Johns\Desktop\Udacity\Meme_Generator\app.py", line 104, in meme_post
    path = meme.make_meme(tmp, body, author)
  File "C:\Users\Johns\Desktop\Udacity\Meme_Generator\MemeGenerator\MemeEngine.py", line 70, in make_meme
    text_draw(draw, text, author, fill, font, width, height)
  File "C:\Users\Johns\Desktop\Udacity\Meme_Generator\utils.py", line 156, in text_draw
    y = random.randint(20, (0.8*height))
  File "C:\Users\Johns\AppData\Local\Programs\Python\Python39\lib\random.py", line 339, in randint
    return self.randrange(a, b+1)
  File "C:\Users\Johns\AppData\Local\Programs\Python\Python39\lib\random.py", line 312, in randrange
    raise ValueError("non-integer stop for randrange()")
ValueError: non-integer stop for randrange()
2021-10-04 21:59:00,611:ERROR:Unable to create meme: non-integer stop for randrange()
Traceback (most recent call last):
  File "C:\Users\Johns\Desktop\Udacity\Meme_Generator\app.py", line 104, in meme_post
    path = meme.make_meme(tmp, body, author)
  File "C:\Users\Johns\Desktop\Udacity\Meme_Generator\MemeGenerator\MemeEngine.py", line 70, in make_meme
    text_draw(draw, text, author, fill, font, width, height)
  File "C:\Users\Johns\Desktop\Udacity\Meme_Generator\utils.py", line 157, in text_draw
    y = random.randint(20, (0.8*height))
  File "C:\Users\Johns\AppData\Local\Programs\Python\Python39\lib\random.py", line 339, in randint
    return self.randrange(a, b+1)
  File "C:\Users\Johns\AppData\Local\Programs\Python\Python39\lib\random.py", line 312, in randrange
    raise ValueError("non-integer stop for randrange()")
ValueError: non-integer stop for randrange()
2021-10-04 22:01:08,931:ERROR:Unable to create meme: non-integer stop for randrange()
Traceback (most recent call last):
  File "C:\Users\Johns\Desktop\Udacity\Meme_Generator\app.py", line 104, in meme_post
    path = meme.make_meme(tmp, body, author)
  File "C:\Users\Johns\Desktop\Udacity\Meme_Generator\MemeGenerator\MemeEngine.py", line 70, in make_meme
    text_draw(draw, text, author, fill, font, width, height)
  File "C:\Users\Johns\Desktop\Udacity\Meme_Generator\utils.py", line 157, in text_draw
    y = random.randint(20, (0.8*int(height)))
  File "C:\Users\Johns\AppData\Local\Programs\Python\Python39\lib\random.py", line 339, in randint
    return self.randrange(a, b+1)
  File "C:\Users\Johns\AppData\Local\Programs\Python\Python39\lib\random.py", line 312, in randrange
    raise ValueError("non-integer stop for randrange()")
ValueError: non-integer stop for randrange()
2021-10-04 22:06:37,271:ERROR:Unable to create meme: non-integer stop for randrange()
Traceback (most recent call last):
  File "C:\Users\Johns\Desktop\Udacity\Meme_Generator\app.py", line 104, in meme_post
    path = meme.make_meme(tmp, body, author)
  File "C:\Users\Johns\Desktop\Udacity\Meme_Generator\MemeGenerator\MemeEngine.py", line 70, in make_meme
    text_draw(draw, text, author, fill, font, int(width), int(height))
  File "C:\Users\Johns\Desktop\Udacity\Meme_Generator\utils.py", line 157, in text_draw
    y = random.randint(20, (0.8*height))
  File "C:\Users\Johns\AppData\Local\Programs\Python\Python39\lib\random.py", line 339, in randint
    return self.randrange(a, b+1)
  File "C:\Users\Johns\AppData\Local\Programs\Python\Python39\lib\random.py", line 312, in randrange
    raise ValueError("non-integer stop for randrange()")
ValueError: non-integer stop for randrange()
2021-10-04 22:07:52,613:ERROR:Unable to create meme: non-integer stop for randrange()
Traceback (most recent call last):
  File "C:\Users\Johns\Desktop\Udacity\Meme_Generator\app.py", line 104, in meme_post
    path = meme.make_meme(tmp, body, author)
  File "C:\Users\Johns\Desktop\Udacity\Meme_Generator\MemeGenerator\MemeEngine.py", line 70, in make_meme
    text_draw(draw, text, author, fill, font, int(width), int(height))
  File "C:\Users\Johns\Desktop\Udacity\Meme_Generator\utils.py", line 159, in text_draw
    y = random.randint(20, y_max)
  File "C:\Users\Johns\AppData\Local\Programs\Python\Python39\lib\random.py", line 339, in randint
    return self.randrange(a, b+1)
  File "C:\Users\Johns\AppData\Local\Programs\Python\Python39\lib\random.py", line 312, in randrange
    raise ValueError("non-integer stop for randrange()")
ValueError: non-integer stop for randrange()
2021-10-04 22:40:31,678:ERROR:Unable to open image url : HTTPSConnectionPool(host='www.test.jpg', port=443): Max retries exceeded with url: / (Caused by NewConnectionError('<urllib3.connection.HTTPSConnection object at 0x00000283B0D09BB0>: Failed to establish a new connection: [Errno 11001] getaddrinfo failed'))
Traceback (most recent call last):
  File "C:\Users\Johns\Desktop\Udacity\Meme_Generator\venv\lib\site-packages\urllib3\connection.py", line 174, in _new_conn
    conn = connection.create_connection(
  File "C:\Users\Johns\Desktop\Udacity\Meme_Generator\venv\lib\site-packages\urllib3\util\connection.py", line 73, in create_connection
    for res in socket.getaddrinfo(host, port, family, socket.SOCK_STREAM):
  File "C:\Users\Johns\AppData\Local\Programs\Python\Python39\lib\socket.py", line 953, in getaddrinfo
    for res in _socket.getaddrinfo(host, port, family, type, proto, flags):
socket.gaierror: [Errno 11001] getaddrinfo failed

During handling of the above exception, another exception occurred:

Traceback (most recent call last):
  File "C:\Users\Johns\Desktop\Udacity\Meme_Generator\venv\lib\site-packages\urllib3\connectionpool.py", line 699, in urlopen
    httplib_response = self._make_request(
  File "C:\Users\Johns\Desktop\Udacity\Meme_Generator\venv\lib\site-packages\urllib3\connectionpool.py", line 382, in _make_request
    self._validate_conn(conn)
  File "C:\Users\Johns\Desktop\Udacity\Meme_Generator\venv\lib\site-packages\urllib3\connectionpool.py", line 1010, in _validate_conn
    conn.connect()
  File "C:\Users\Johns\Desktop\Udacity\Meme_Generator\venv\lib\site-packages\urllib3\connection.py", line 358, in connect
    conn = self._new_conn()
  File "C:\Users\Johns\Desktop\Udacity\Meme_Generator\venv\lib\site-packages\urllib3\connection.py", line 186, in _new_conn
    raise NewConnectionError(
urllib3.exceptions.NewConnectionError: <urllib3.connection.HTTPSConnection object at 0x00000283B0D09BB0>: Failed to establish a new connection: [Errno 11001] getaddrinfo failed

During handling of the above exception, another exception occurred:

Traceback (most recent call last):
  File "C:\Users\Johns\Desktop\Udacity\Meme_Generator\venv\lib\site-packages\requests\adapters.py", line 439, in send
    resp = conn.urlopen(
  File "C:\Users\Johns\Desktop\Udacity\Meme_Generator\venv\lib\site-packages\urllib3\connectionpool.py", line 755, in urlopen
    retries = retries.increment(
  File "C:\Users\Johns\Desktop\Udacity\Meme_Generator\venv\lib\site-packages\urllib3\util\retry.py", line 574, in increment
    raise MaxRetryError(_pool, url, error or ResponseError(cause))
urllib3.exceptions.MaxRetryError: HTTPSConnectionPool(host='www.test.jpg', port=443): Max retries exceeded with url: / (Caused by NewConnectionError('<urllib3.connection.HTTPSConnection object at 0x00000283B0D09BB0>: Failed to establish a new connection: [Errno 11001] getaddrinfo failed'))

During handling of the above exception, another exception occurred:

Traceback (most recent call last):
  File "C:\Users\Johns\Desktop\Udacity\Meme_Generator\app.py", line 91, in meme_post
    img_content = requests.get(image_url, stream=True).content
  File "C:\Users\Johns\Desktop\Udacity\Meme_Generator\venv\lib\site-packages\requests\api.py", line 75, in get
    return request('get', url, params=params, **kwargs)
  File "C:\Users\Johns\Desktop\Udacity\Meme_Generator\venv\lib\site-packages\requests\api.py", line 61, in request
    return session.request(method=method, url=url, **kwargs)
  File "C:\Users\Johns\Desktop\Udacity\Meme_Generator\venv\lib\site-packages\requests\sessions.py", line 542, in request
    resp = self.send(prep, **send_kwargs)
  File "C:\Users\Johns\Desktop\Udacity\Meme_Generator\venv\lib\site-packages\requests\sessions.py", line 655, in send
    r = adapter.send(request, **kwargs)
  File "C:\Users\Johns\Desktop\Udacity\Meme_Generator\venv\lib\site-packages\requests\adapters.py", line 516, in send
    raise ConnectionError(e, request=request)
requests.exceptions.ConnectionError: HTTPSConnectionPool(host='www.test.jpg', port=443): Max retries exceeded with url: / (Caused by NewConnectionError('<urllib3.connection.HTTPSConnection object at 0x00000283B0D09BB0>: Failed to establish a new connection: [Errno 11001] getaddrinfo failed'))
